Workbook

Sheet Summary
A1: PJ22045_1R8T Channel Register Map v0.2 (RegMap v8 + mem39, cal_plus_gain_control_ch1~8 / addressable_reg_map)
A3: Base address (hex) | B3: A0090000
A4: Channel bases | B4: ch1~ch8 = 0xA009_0000 + 0x1000 x (N-1) (ch1 0xA009_0000 ... ch8 0xA009_7000); gain BRAM 0xA009_A000 + 0x2000 x (N-1); see sheet Channel_Map (design_1 Address Editor, build 02)
A5: AXI-Lite range | B5: 4 KB window, 128 x 32-bit registers (mem0~127), 9-bit address
A6: Clock | B6: S_AXI_ACLK = pl_clk0 (100 MHz)
A7: Version | B7: v0.2 (2026-10-19, Debug_008): mem39 signal_source_select 1 -> 2 bit, 2 / 3 = all_zero (160'd0, tvalid = 1). v0.1 (2026-10-15, PJ22045_1R8T build 02): register definition = Calibration_Gain_Control Reg_map_tx_ch_v0.2 (RegMap v8).
A8: Source | B8: docs/02_RFSoC_TX/tools/regmap_def.py (copy of Calibration_Gain_Control/doc/tools/regmap_def.py) -> docs/02_RFSoC_TX/tools/mk_regmap_v8.py (this file)
A10: Legend
A11: Yellow cell | B11: Input: change the base address here (e.g. A0092000 for ch3); all addresses follow
A12: Grey / green rows | B12: Configuration registers (R/W)
A13: Blue rows | B13: Status registers: write status_snapshot (mem64) = 1, then read mem65~70 (one consistent snapshot)
A15: Notes
A16: 1 | B16: All configuration registers are R/W 32-bit; unused upper bits read back what was written and are ignored by the hardware.
A17: 2 | B17: Non-zero reset: dac_output_ref_dbm (mem25) = 0x670 (-25 dBm), goal_ref_dbfs (mem26) = 0x7A0 (-6.0 dBFS), agc_reg5 (mem27) = 0x80 (RX mode).
A18: 3 | B18: dBFS: 16384 = 0 dBFS. S6.4 = 11-bit two's complement, 1/16 dB (e.g. -6.0 dB = -96 = 0x7A0).
A19: 4 | B19: Status: status_snapshot read value = completed snapshot count [15:0]; it increments when both clk (256 MHz) and adc_clk (240 MHz) domains have latched. Signed status fields are sign-extended to 32 bit.
A20: 6 | B20: bypass_axis_iq (mem38) = 1: m_axis_iq = Signal Source Mux output (FIR / calibration / gain control bypassed, 0 latency mux); the normal path keeps running so AGC / Power Fit status is still valid. Debug only.
A21: 8 | B21: PJ22045_1R8T: s_axis_iq_in_0 = Aurora (hier_rx_x0yN/M_AXIS_Cx), s_axis_iq_in_1 = local ADC (rfdc_iq_combine_chN). Boot default (software reg_map_cfg.c): mem39 = 0 (Aurora), mem38 = 0, FIR = impulse response (tap7 I = 0x7FFF). Debug_008 PS: ch1 only mem39 = 2 (all_zero) + mem38 = 1; ch2~ch8 = 0 / 0.
A22: 7 | B22: signal_source_select (mem39): Signal Source Mux in front of the mem38 bypass. 0 = s_axis_iq_in_0, 1 = s_axis_iq_in_1, 2 / 3 = all_zero (Debug_008, 160'd0 with tvalid = 1); the selected stream feeds Power Fit / Calibration (and the bypass path). 0 latency mux; unselected inputs are dropped (tready = 1). All on clk (256 MHz).
A23: 5 | B23: Moved to system_reg_map (v7 -> v8): signal_mode_select (mem26), power_limit_margin (mem27), cw_mode_goal_amp (mem20 -> cw_mode_goal_dbfs), digital_apply_delay (mem30), agc_tx_power_mode (mem36), agc_rx_*_cycle (mem44~49), agc_sr_update_period (mem50), agc_mode_settle_cycle (mem51).

Sheet Channel_Map
A1: Ch | B1: Reg map base | C1: Gain BRAM base | D1: in_0 (Aurora) | E1: in_1 (ADC -> combiner) | F1: DAC | G1: adc_clk | H1: RFDC flag / clear | I1: VIO probe_out
A2: ch1 | B2: 0xA0090000 | C2: 0xA009A000 | D2: hier_rx_x0y2 / M_AXIS_C0 | E2: m00 / m01 | F2: s00 | G2: clk_adc0 | H2: adc0_01 | I2: 0 ~ 3
A3: ch2 | B3: 0xA0091000 | C3: 0xA009C000 | D3: hier_rx_x0y2 / M_AXIS_C1 | E3: m02 / m03 | F3: s02 | G3: clk_adc0 | H3: adc0_23 | I3: 4 ~ 7
A4: ch3 | B4: 0xA0092000 | C4: 0xA009E000 | D4: hier_rx_x0y1 / M_AXIS_C0 | E4: m10 / m11 | F4: s10 | G4: clk_adc1 | H4: adc1_01 | I4: 8 ~ 11
A5: ch4 | B5: 0xA0093000 | C5: 0xA00A0000 | D5: hier_rx_x0y1 / M_AXIS_C1 | E5: m12 / m13 | F5: s12 | G5: clk_adc1 | H5: adc1_23 | I5: 12 ~ 15
A6: ch5 | B6: 0xA0094000 | C6: 0xA00A2000 | D6: hier_rx_x0y3 / M_AXIS_C0 | E6: m20 / m21 | F6: s20 | G6: clk_adc2 | H6: adc2_01 | I6: 16 ~ 19
A7: ch6 | B7: 0xA0095000 | C7: 0xA00A4000 | D7: hier_rx_x0y3 / M_AXIS_C1 | E7: m22 / m23 | F7: s22 | G7: clk_adc2 | H7: adc2_23 | I7: 20 ~ 23
A8: ch7 | B8: 0xA0096000 | C8: 0xA00A6000 | D8: hier_rx_x0y4 / M_AXIS_C0 | E8: m30 / m31 | F8: s30 | G8: clk_adc3 | H8: adc3_01 | I8: 24 ~ 27
A9: ch8 | B9: 0xA0097000 | C9: 0xA00A8000 | D9: hier_rx_x0y4 / M_AXIS_C1 | E9: m32 / m33 | F9: s32 | G9: clk_adc3 | H9: adc3_23 | I9: 28 ~ 31
A11: system_reg_map: 0xA009_8000 (sheet in Reg_map_emu_sys).
A12: All channels: clk = FPGA_clk 256 MHz, S_AXI_ACLK = pl_clk0 100 MHz, adc_clk = clk_adcN 240 MHz.
A13: VIO probes per channel: rx_att_index[2:0], algo_analog_att_db[8:0], pulse_avg_amp[15:0], pulse_papr[8:0].

Sheet Register_Map
A1: Index | B1: Offset (hex) | C1: Address | D1: Register Name | E1: Bits | F1: R/W | G1: Reset (hex) | H1: Format / Unit | I1: Range / Values | J1: Description | K1: Takes effect | L1: Used by (BD) | M1: Group
A2: mem0 | B2: 000 | C2: ="0x"&DEC2HEX(HEX2DEC(Summary!$B$3)+0,8) | D2: fir_enable | E2: [0] | F2: R/W | G2: 0 | H2: bit | I2: 0 / 1 | J2: Complex FIR enable | K2: - | L2: in_band_flatness/sl_fir_enable | M2: Calibration
A3: mem1 | B3: 004 | C3: ="0x"&DEC2HEX(HEX2DEC(Summary!$B$3)+4,8) | D3: fir_tap00 | E3: [31:0] | F3: R/W | G3: 0 | H3: [15:0] I, [31:16] Q (S0.15 each, 0x7FFF ≈ 1.0) | I3: - | J3: Complex FIR tap 00 coefficient | K3: - | L3: in_band_flatness/FIR_coef_unpack_0 | M3: Calibration
A4: mem2 | B4: 008 | C4: ="0x"&DEC2HEX(HEX2DEC(Summary!$B$3)+8,8) | D4: fir_tap01 | E4: [31:0] | F4: R/W | G4: 0 | H4: [15:0] I, [31:16] Q (S0.15 each, 0x7FFF ≈ 1.0) | I4: - | J4: Complex FIR tap 01 coefficient | K4: - | L4: in_band_flatness/FIR_coef_unpack_0 | M4: Calibration
A5: mem3 | B5: 00C | C5: ="0x"&DEC2HEX(HEX2DEC(Summary!$B$3)+12,8) | D5: fir_tap02 | E5: [31:0] | F5: R/W | G5: 0 | H5: [15:0] I, [31:16] Q (S0.15 each, 0x7FFF ≈ 1.0) | I5: - | J5: Complex FIR tap 02 coefficient | K5: - | L5: in_band_flatness/FIR_coef_unpack_0 | M5: Calibration
A6: mem4 | B6: 010 | C6: ="0x"&DEC2HEX(HEX2DEC(Summary!$B$3)+16,8) | D6: fir_tap03 | E6: [31:0] | F6: R/W | G6: 0 | H6: [15:0] I, [31:16] Q (S0.15 each, 0x7FFF ≈ 1.0) | I6: - | J6: Complex FIR tap 03 coefficient | K6: - | L6: in_band_flatness/FIR_coef_unpack_0 | M6: Calibration
A7: mem5 | B7: 014 | C7: ="0x"&DEC2HEX(HEX2DEC(Summary!$B$3)+20,8) | D7: fir_tap04 | E7: [31:0] | F7: R/W | G7: 0 | H7: [15:0] I, [31:16] Q (S0.15 each, 0x7FFF ≈ 1.0) | I7: - | J7: Complex FIR tap 04 coefficient | K7: - | L7: in_band_flatness/FIR_coef_unpack_0 | M7: Calibration
A8: mem6 | B8: 018 | C8: ="0x"&DEC2HEX(HEX2DEC(Summary!$B$3)+24,8) | D8: fir_tap05 | E8: [31:0] | F8: R/W | G8: 0 | H8: [15:0] I, [31:16] Q (S0.15 each, 0x7FFF ≈ 1.0) | I8: - | J8: Complex FIR tap 05 coefficient | K8: - | L8: in_band_flatness/FIR_coef_unpack_0 | M8: Calibration
A9: mem7 | B9: 01C | C9: ="0x"&DEC2HEX(HEX2DEC(Summary!$B$3)+28,8) | D9: fir_tap06 | E9: [31:0] | F9: R/W | G9: 0 | H9: [15:0] I, [31:16] Q (S0.15 each, 0x7FFF ≈ 1.0) | I9: - | J9: Complex FIR tap 06 coefficient | K9: - | L9: in_band_flatness/FIR_coef_unpack_0 | M9: Calibration
A10: mem8 | B10: 020 | C10: ="0x"&DEC2HEX(HEX2DEC(Summary!$B$3)+32,8) | D10: fir_tap07 | E10: [31:0] | F10: R/W | G10: 0 | H10: [15:0] I, [31:16] Q (S0.15 each, 0x7FFF ≈ 1.0) | I10: - | J10: Complex FIR tap 07 coefficient | K10: - | L10: in_band_flatness/FIR_coef_unpack_0 | M10: Calibration
A11: mem9 | B11: 024 | C11: ="0x"&DEC2HEX(HEX2DEC(Summary!$B$3)+36,8) | D11: fir_tap08 | E11: [31:0] | F11: R/W | G11: 0 | H11: [15:0] I, [31:16] Q (S0.15 each, 0x7FFF ≈ 1.0) | I11: - | J11: Complex FIR tap 08 coefficient | K11: - | L11: in_band_flatness/FIR_coef_unpack_0 | M11: Calibration
A12: mem10 | B12: 028 | C12: ="0x"&DEC2HEX(HEX2DEC(Summary!$B$3)+40,8) | D12: fir_tap09 | E12: [31:0] | F12: R/W | G12: 0 | H12: [15:0] I, [31:16] Q (S0.15 each, 0x7FFF ≈ 1.0) | I12: - | J12: Complex FIR tap 09 coefficient | K12: - | L12: in_band_flatness/FIR_coef_unpack_0 | M12: Calibration
A13: mem11 | B13: 02C | C13: ="0x"&DEC2HEX(HEX2DEC(Summary!$B$3)+44,8) | D13: fir_tap10 | E13: [31:0] | F13: R/W | G13: 0 | H13: [15:0] I, [31:16] Q (S0.15 each, 0x7FFF ≈ 1.0) | I13: - | J13: Complex FIR tap 10 coefficient | K13: - | L13: in_band_flatness/FIR_coef_unpack_0 | M13: Calibration
A14: mem12 | B14: 030 | C14: ="0x"&DEC2HEX(HEX2DEC(Summary!$B$3)+48,8) | D14: fir_tap11 | E14: [31:0] | F14: R/W | G14: 0 | H14: [15:0] I, [31:16] Q (S0.15 each, 0x7FFF ≈ 1.0) | I14: - | J14: Complex FIR tap 11 coefficient | K14: - | L14: in_band_flatness/FIR_coef_unpack_0 | M14: Calibration
A15: mem13 | B15: 034 | C15: ="0x"&DEC2HEX(HEX2DEC(Summary!$B$3)+52,8) | D15: fir_tap12 | E15: [31:0] | F15: R/W | G15: 0 | H15: [15:0] I, [31:16] Q (S0.15 each, 0x7FFF ≈ 1.0) | I15: - | J15: Complex FIR tap 12 coefficient | K15: - | L15: in_band_flatness/FIR_coef_unpack_0 | M15: Calibration
A16: mem14 | B16: 038 | C16: ="0x"&DEC2HEX(HEX2DEC(Summary!$B$3)+56,8) | D16: fir_tap13 | E16: [31:0] | F16: R/W | G16: 0 | H16: [15:0] I, [31:16] Q (S0.15 each, 0x7FFF ≈ 1.0) | I16: - | J16: Complex FIR tap 13 coefficient | K16: - | L16: in_band_flatness/FIR_coef_unpack_0 | M16: Calibration
A17: mem15 | B17: 03C | C17: ="0x"&DEC2HEX(HEX2DEC(Summary!$B$3)+60,8) | D17: fir_tap14 | E17: [31:0] | F17: R/W | G17: 0 | H17: [15:0] I, [31:16] Q (S0.15 each, 0x7FFF ≈ 1.0) | I17: - | J17: Complex FIR tap 14 coefficient | K17: - | L17: in_band_flatness/FIR_coef_unpack_0 | M17: Calibration
A18: mem16 | B18: 040 | C18: ="0x"&DEC2HEX(HEX2DEC(Summary!$B$3)+64,8) | D18: fir_tap15 | E18: [31:0] | F18: R/W | G18: 0 | H18: [15:0] I, [31:16] Q (S0.15 each, 0x7FFF ≈ 1.0) | I18: - | J18: Complex FIR tap 15 coefficient | K18: - | L18: in_band_flatness/FIR_coef_unpack_0 | M18: Calibration
A19: mem17 | B19: 044 | C19: ="0x"&DEC2HEX(HEX2DEC(Summary!$B$3)+68,8) | D19: coarse_delay_offset | E19: [3:0] | F19: R/W | G19: 0 | H19: unsigned, cycles | I19: 0 ~ 15 | J19: Delay_Cal coarse delay | K19: Real-time (CDC) | L19: cal_cdc_0 -> calibration/Delay_Cal_0 | M19: Calibration
A20: mem18 | B20: 048 | C20: ="0x"&DEC2HEX(HEX2DEC(Summary!$B$3)+72,8) | D20: fractional_delay_offset | E20: [2:0] | F20: R/W | G20: 0 | H20: unsigned, samples | I20: 0 ~ 4 | J20: Delay_Cal fractional delay | K20: Real-time (CDC) | L20: cal_cdc_0 -> calibration/Delay_Cal_0 | M20: Calibration
A21: mem19 | B21: 04C | C21: ="0x"&DEC2HEX(HEX2DEC(Summary!$B$3)+76,8) | D21: phase_offset | E21: [15:0] | F21: R/W | G21: 0 | H21: CORDIC phase | I21: - | J21: Phase_Cal phase offset (cordic_0~4) | K21: Real-time (CDC) | L21: cal_cdc_0 -> calibration/cordic_0~4 | M21: Calibration
A22: mem20 | B22: 050 | C22: ="0x"&DEC2HEX(HEX2DEC(Summary!$B$3)+80,8) | D22: gain_index_mode_sel | E22: [0] | F22: R/W | G22: 0 | H22: bit | I22: 0: TXAGC, 1: manual | J22: Gain_Compensation index source: 0 = gain_index_tx (TXAGC digital), 1 = gain_index_manual | K22: Real-time (CDC) | L22: cal_cdc_0 -> gain_index_mux_0 | M22: Gain Index
A23: mem21 | B23: 054 | C23: ="0x"&DEC2HEX(HEX2DEC(Summary!$B$3)+84,8) | D23: gain_index_manual | E23: [10:0] | F23: R/W | G23: 0 | H23: S6.4, 1/16 dB | I23: -64 ~ +63.9375 dB | J23: Manual gain index (mode_sel = 1), offsets not added | K23: Real-time (CDC) | L23: cal_cdc_0 -> gain_index_mux_0 | M23: Gain Index
A24: mem22 | B24: 058 | C24: ="0x"&DEC2HEX(HEX2DEC(Summary!$B$3)+88,8) | D24: gain_index_ch_offset | E24: [8:0] | F24: R/W | G24: 0 | H24: S4.4, 1/16 dB | I24: -16 ~ +15.9375 dB | J24: Channel magnitude trim (+ = gain), in the TXAGC target (analog first, residual digital) | K24: Real-time | L24: agc_emu/agc_cdc_0 -> txagc_0 | M24: Gain Index
A25: mem23 | B25: 05C | C25: ="0x"&DEC2HEX(HEX2DEC(Summary!$B$3)+92,8) | D25: gain_index_rf_freq_offset | E25: [7:0] | F25: R/W | G25: 0 | H25: S3.4, 1/16 dB | I25: -8 ~ +7.9375 dB | J25: RF-frequency magnitude trim (+ = gain), in the TXAGC target | K25: Real-time | L25: agc_emu/agc_cdc_0 -> txagc_0 | M25: Gain Index
A26: mem24 | B26: 060 | C26: ="0x"&DEC2HEX(HEX2DEC(Summary!$B$3)+96,8) | D26: gain_index_temperature_offset | E26: [7:0] | F26: R/W | G26: 0 | H26: S3.4, 1/16 dB | I26: -8 ~ +7.9375 dB | J26: Temperature magnitude trim (+ = gain), in the TXAGC target | K26: Real-time | L26: agc_emu/agc_cdc_0 -> txagc_0 | M26: Gain Index
A27: mem25 | B27: 064 | C27: ="0x"&DEC2HEX(HEX2DEC(Summary!$B$3)+100,8) | D27: dac_output_ref_dbm | E27: [10:0] | F27: R/W | G27: 670 (-25) | H27: S6.4 dBm | I27: HW limit +10 ~ -40 dBm | J27: DAC output measured with goal = goal_ref_dbfs (TXAGC Manual mode reference) | K27: Real-time | L27: agc_emu/agc_cdc_0 -> txagc_0 | M27: Gain Index
A28: mem26 | B28: 068 | C28: ="0x"&DEC2HEX(HEX2DEC(Summary!$B$3)+104,8) | D28: goal_ref_dbfs | E28: [10:0] | F28: R/W | G28: 7A0 (-6) | H28: S6.4 dBFS (16384 = 0 dBFS) | I28: -64 ~ +63.9375 dB | J28: Goal (dBFS) used when dac_output_ref_dbm was measured; goal_rel_db = goal_dBFS - goal_ref_dbfs | K28: Real-time (CDC) | L28: cal_cdc_0 -> power_fit_top/power_fit_db_0 | M28: Gain Index
A29: mem27 | B29: 06C | C29: ="0x"&DEC2HEX(HEX2DEC(Summary!$B$3)+108,8) | D29: agc_reg5 | E29: [7:0] | F29: R/W | G29: 80 | H29: bits | I29: [7] TXRX_SW: 0 TX, 1 RX; [6:2] filter; [1:0] PA on = 11 | J29: Reg5 byte (595 QA~QH). [7] TXRX_SW = AGC mode source; [6:2] Filter {Vc2, Vc1, Vc0, Vc3, Vc4}; [1] PA_VC_D, [0] PA_VC_G | K29: Real-time (bypass: agc_bypass_sr_update[1]) | L29: agc_emu/agc_cdc_0 -> agc_mode_ctrl_0 / sr_src_mux_0 | M29: AGC_EMU
A30: mem28 | B30: 070 | C30: ="0x"&DEC2HEX(HEX2DEC(Summary!$B$3)+112,8) | D30: agc_bypass_agc | E30: [0] | F30: R/W | G30: 0 | H30: bit | I30: 0: AGC, 1: bypass | J30: 1: AGC paused; TX attenuator = agc_bypass_tx_att_state, RX = dummy 0 dB, digital comp = 0; SR sent only by agc_bypass_sr_update | K30: Real-time | L30: agc_emu/agc_cdc_0 | M30: AGC_EMU
A31: mem29 | B31: 074 | C31: ="0x"&DEC2HEX(HEX2DEC(Summary!$B$3)+116,8) | D31: agc_bypass_tx_att_state | E31: [4:0] | F31: R/W | G31: 0 | H31: unsigned state | I31: 0 ~ 27 (0 = 130 dB ... 27 = 5 dB) | J31: TX analog attenuator state in bypass | K31: Bypass trigger | L31: agc_emu/agc_cdc_0 -> txagc_0 | M31: AGC_EMU
A32: mem30 | B32: 078 | C32: ="0x"&DEC2HEX(HEX2DEC(Summary!$B$3)+120,8) | D32: agc_bypass_sr_update | E32: [1:0] | F32: R/W | G32: 0 | H32: bits, rising edge | I32: write 1 then 0 (0x3 = all 5 registers) | J32: Bypass only. [0] send Reg1~4, [1] send Reg5 | K32: - | L32: agc_emu/agc_cdc_0 -> sr_src_mux_0 | M32: AGC_EMU
A33: mem31 | B33: 07C | C33: ="0x"&DEC2HEX(HEX2DEC(Summary!$B$3)+124,8) | D33: agc_manual_tx_att_en | E33: [0] | F33: R/W | G33: 0 | H33: bit | I33: 0: formula, 1: manual | J33: TX target attenuation = agc_manual_tx_att_db (other TX inputs ignored) | K33: Real-time | L33: agc_emu/agc_cdc_0 -> txagc_0 | M33: AGC_EMU
A34: mem32 | B34: 080 | C34: ="0x"&DEC2HEX(HEX2DEC(Summary!$B$3)+128,8) | D34: agc_manual_tx_att_db | E34: [7:0] | F34: R/W | G34: 0 | H34: unsigned, 1 dB | I34: 5 ~ 130 | J34: Manual TX target attenuation | K34: Real-time | L34: agc_emu/agc_cdc_0 -> txagc_0 | M34: AGC_EMU
A35: mem33 | B35: 084 | C35: ="0x"&DEC2HEX(HEX2DEC(Summary!$B$3)+132,8) | D35: agc_target_power | E35: [7:0] | F35: R/W | G35: 0 | H35: signed, 1 dBm | I35: -128 ~ +127 dBm | J35: Manual mode target output power (e.g. 0xD8 = -40 dBm) | K35: Real-time | L35: agc_emu/agc_cdc_0 -> txagc_0 | M35: AGC_EMU
A36: mem34 | B36: 088 | C36: ="0x"&DEC2HEX(HEX2DEC(Summary!$B$3)+136,8) | D36: agc_linear_mode_offset | E36: [11:0] | F36: R/W | G36: 0 | H36: signed, 1/16 dB | I36: -128 ~ +127.9375 dB | J36: Linear mode offset | K36: Real-time | L36: agc_emu/agc_cdc_0 -> txagc_0 | M36: AGC_EMU
A37: mem35 | B37: 08C | C37: ="0x"&DEC2HEX(HEX2DEC(Summary!$B$3)+140,8) | D37: agc_manual_mode_offset | E37: [11:0] | F37: R/W | G37: 0 | H37: signed, 1/16 dB | I37: -128 ~ +127.9375 dB | J37: Manual mode offset | K37: Real-time | L37: agc_emu/agc_cdc_0 -> txagc_0 | M37: AGC_EMU
A38: mem36 | B38: 090 | C38: ="0x"&DEC2HEX(HEX2DEC(Summary!$B$3)+144,8) | D38: agc_manual_rx_att_en | E38: [0] | F38: R/W | G38: 0 | H38: bit | I38: 0: RXAGC, 1: manual | J38: Use agc_manual_rx_att_state instead of the RXAGC result (RX mode) | K38: Real-time | L38: agc_emu/agc_cdc_0 -> rxagc_0 | M38: AGC_EMU
A39: mem37 | B39: 094 | C39: ="0x"&DEC2HEX(HEX2DEC(Summary!$B$3)+148,8) | D39: agc_manual_rx_att_state | E39: [2:0] | F39: R/W | G39: 0 | H39: unsigned state | I39: 0 ~ 6 (0 ~ 60 dB) | J39: Manual RX attenuation state | K39: Real-time | L39: agc_emu/agc_cdc_0 -> rxagc_0 | M39: AGC_EMU
A40: mem38 | B40: 098 | C40: ="0x"&DEC2HEX(HEX2DEC(Summary!$B$3)+152,8) | D40: bypass_axis_iq | E40: [0] | F40: R/W | G40: 0 | H40: bit | I40: 0: normal, 1: bypass | J40: Debug: 1 = m_axis_iq = Signal Source Mux output (mem39 selected input; FIR / calibration / gain control bypassed, input sent directly to the DAC); the normal path keeps running (AGC / Power Fit still computed) | K40: Real-time (CDC) | L40: cal_cdc_0 -> axis_iq_bypass_0 | M40: Calibration
...

Sheet v7_to_v8
A1: v7 mem | B1: v7 name | C1: v8 location | D1: v8 name | E1: Note
A2: 20 | B2: cw_mode_goal_amp | C2: sys2 | D2: cw_mode_goal_dbfs | E2: amplitude -> S6.4 dBFS
A3: 21 | B3: gain_index_mode_sel | C3: mem20 | D3: gain_index_mode_sel
A4: 22 | B4: gain_index_manual | C4: mem21 | D4: gain_index_manual
A5: 23 | B5: gain_index_ch_offset | C5: mem22 | D5: gain_index_ch_offset
A6: 24 | B6: gain_index_rf_freq_offset | C6: mem23 | D6: gain_index_rf_freq_offset
A7: 25 | B7: gain_index_temperature_offset | C7: mem24 | D7: gain_index_temperature_offset
A8: 26 | B8: signal_mode_select | C8: sys0 | D8: signal_mode_select
A9: 27 | B9: power_limit_margin | C9: sys1 | D9: power_limit_margin
A10: 28 | B10: dac_output_ref_dbm | C10: mem25 | D10: dac_output_ref_dbm
A11: 29 | B11: goal_ref_amp | C11: mem26 | D11: goal_ref_dbfs | E11: amplitude -> S6.4 dBFS
A12: 30 | B12: digital_apply_delay | C12: sys5 | D12: digital_apply_delay
A13: 31 | B13: (reserved) | C13: - | D13: -
A14: 32 | B14: agc_reg5 | C14: mem27 | D14: agc_reg5
A15: 33 | B15: agc_bypass_agc | C15: mem28 | D15: agc_bypass_agc
A16: 34 | B16: agc_bypass_tx_att_state | C16: mem29 | D16: agc_bypass_tx_att_state
A17: 35 | B17: agc_bypass_sr_update | C17: mem30 | D17: agc_bypass_sr_update
A18: 36 | B18: agc_tx_power_mode | C18: sys4 | D18: agc_tx_power_mode
A19: 37 | B19: agc_manual_tx_att_en | C19: mem31 | D19: agc_manual_tx_att_en
A20: 38 | B20: agc_manual_tx_att_db | C20: mem32 | D20: agc_manual_tx_att_db
A21: 39 | B21: agc_target_power | C21: mem33 | D21: agc_target_power
A22: 40 | B22: agc_linear_mode_offset | C22: mem34 | D22: agc_linear_mode_offset
A23: 41 | B23: agc_manual_mode_offset | C23: mem35 | D23: agc_manual_mode_offset
... A33: 51 | B33: agc_mode_settle_cycle | C33: sys7 | D33: agc_mode_settle_cycle
A35: mem0~19 (FIR, delay, phase) unchanged.

Sheet BD_IO
A1: Port | B1: Direction | C1: Width | D1: Clock domain | E1: Connected to (design_1) | F1: Description
A2: s_axis_iq_in_0 / s_axis_iq_in_1 | B2: in | C2: AXIS [159:0] each | D2: clk (256 MHz) | E2: s_axis_iq_in_0: Aurora hier_rx_x0yN/M_AXIS_Cx; s_axis_iq_in_1: rfdc_iq_combine_chN (ADC) | F2: Signal Source Mux inputs (mem39 selects); 5 samples x {Q[15:0], I[15:0]} per beat
A3: m_axis_iq | B3: out | C3: AXIS [159:0] | D3: clk (256 MHz) | E3: RFDC DAC | F3: Calibrated output (or mux output when mem38 bypass = 1)
A4: reg_signal_mode_select / reg_power_limit_margin / reg_cw_mode_goal_dbfs / reg_pulse_update_stable_cycle | B4: in | C4: [31:0] each | D4: S_AXI_ACLK | E4: system_reg_map/sys0~3 (nets reg_<name>) | F4: System Power Fit settings -> cal_cdc_0
A5: reg_agc_tx_power_mode / reg_digital_apply_delay / reg_agc_sr_update_period / reg_agc_mode_settle_cycle / reg_agc_rx_*_cycle | B5: in | C5: [31:0] each | D5: S_AXI_ACLK | E5: system_reg_map/sys4~13 | F5: System AGC settings -> agc_emu (agc_cdc_0)
A6: rx_att_index | B6: in | C6: [2:0] | D6: clk (256 MHz) | E6: vio_ext_inputs probe 4(N-1) (temporary) | F6: RSP RX attenuation index 0~6 x 10 dB
A7: algo_analog_att_db | B7: in | C7: [8:0] | D7: clk | E7: vio_ext_inputs (temporary) | F7: S8.0 dB extra analog attenuation
A8: pulse_avg_amp | B8: in | C8: [15:0] | D8: clk | E8: vio_ext_inputs (temporary) | F8: Pulse mode Power Fit input (auto update: latched together with PAPR after M stable clk)
A9: pulse_papr | B9: in | C9: [8:0] | D9: clk | E9: vio_ext_inputs (temporary) | F9: U5.4 dB; Pulse goal = -(margin + PAPR) dBFS
A10: adc_clk | B10: in | C10: 1 | D10: - | E10: RFDC clk_adcN (240 MHz) | F10: AGC clock
A11: over_voltage / over_range / over_threshold1 / over_threshold2 | B11: in | C11: 1 each | D11: adc_clk | E11: RFDC adcN_01_* | F11: RXAGC flags (also st_adc_flags)
A12: clear_or / clear_ov | B12: out | C12: 1 each | D12: S_AXI_ACLK | E12: RFDC adcN_01_clear_* | F12: Flag clear
A13: Reg1~5_SER / SRCLK / RCLK | B13: out | C13: 15 | D13: adc_clk | E13: CHN_Reg1~5_* top ports | F13: 74LVC595 pins

Sheet Examples
A1: Step | B1: Register | C1: Address | D1: Write value (hex) | E1: Comment
A2: A. Status snapshot (reg_rt.tcl: reg_dump)
A3: 1 | B3: status_snapshot (mem64) | C3: ="0x"&DEC2HEX(HEX2DEC(Summary!$B$3)+256,8) | D3: 00000001 | E3: latch all st_* of this channel
A4: 2 | B4: status_snapshot (mem64) | C4: ="0x"&DEC2HEX(HEX2DEC(Summary!$B$3)+256,8) | D4: (read) | E4: count changed -> snapshot done
A5: 3 | B5: st_power_amp ~ st_adc_flags (mem65~70) | C5: ="0x"&DEC2HEX(HEX2DEC(Summary!$B$3)+260,8) | D5: (read) | E5: pf / goal / goal_rel / gain_index_tx: S?.4 sign-extended, /16 = dB
A6: B. TX Manual with DAC reference (goal -6 dBFS measured at -25 dBm), target -40 dBm
A7: 1 | B7: goal_ref_dbfs (mem26) | C7: ="0x"&DEC2HEX(HEX2DEC(Summary!$B$3)+104,8) | D7: 000007A0 | E7: -6.0 dBFS
A8: 2 | B8: dac_output_ref_dbm (mem25) | C8: ="0x"&DEC2HEX(HEX2DEC(Summary!$B$3)+100,8) | D8: 00000670 | E8: -25 dBm (S6.4)
A9: 3 | B9: agc_target_power (mem33) | C9: ="0x"&DEC2HEX(HEX2DEC(Summary!$B$3)+132,8) | D9: 000000D8 | E9: -40 dBm; agc_tx_power_mode (system sys4) = 1
A10: C. Bypass
A11: 1 | B11: agc_bypass_agc (mem28) | C11: ="0x"&DEC2HEX(HEX2DEC(Summary!$B$3)+112,8) | D11: 00000001 | E11: AGC paused
A12: 2 | B12: agc_bypass_tx_att_state (mem29) | C12: ="0x"&DEC2HEX(HEX2DEC(Summary!$B$3)+116,8) | D12: 00000016 | E12: TX state 22 (25 dB)
A13: 3 | B13: agc_bypass_sr_update (mem30) | C13: ="0x"&DEC2HEX(HEX2DEC(Summary!$B$3)+120,8) | D13: 00000003 | E13: rising edge: send Reg1~4 + Reg5
A14: 4 | B14: agc_bypass_sr_update (mem30) | C14: ="0x"&DEC2HEX(HEX2DEC(Summary!$B$3)+120,8) | D14: 00000000 | E14: clear
A15: 5 | B15: agc_bypass_agc (mem28) | C15: ="0x"&DEC2HEX(HEX2DEC(Summary!$B$3)+112,8) | D15: 00000000 | E15: back to AGC
A16: D. Manual TX 48 dB
A17: 1 | B17: agc_manual_tx_att_db (mem32) | C17: ="0x"&DEC2HEX(HEX2DEC(Summary!$B$3)+128,8) | D17: 00000030 | E17: 48 dB -> analog 45 dB + digital 3 dB
A18: 2 | B18: agc_manual_tx_att_en (mem31) | C18: ="0x"&DEC2HEX(HEX2DEC(Summary!$B$3)+124,8) | D18: 00000001
A19: E. Debug: send the input directly to the DAC
A20: 1 | B20: bypass_axis_iq (mem38) | C20: ="0x"&DEC2HEX(HEX2DEC(Summary!$B$3)+152,8) | D20: 00000001 | E20: m_axis_iq = mux output (no FIR / calibration / gain)
A21: 2 | B21: bypass_axis_iq (mem38) | C21: ="0x"&DEC2HEX(HEX2DEC(Summary!$B$3)+152,8) | D21: 00000000 | E21: back to the normal path
A22: F. Signal source
A23: 1 | B23: signal_source_select (mem39) | C23: ="0x"&DEC2HEX(HEX2DEC(Summary!$B$3)+156,8) | D23: 00000001 | E23: Power Fit / Calibration use s_axis_iq_in_1
A24: 2 | B24: signal_source_select (mem39) | C24: ="0x"&DEC2HEX(HEX2DEC(Summary!$B$3)+156,8) | D24: 00000000 | E24: back to s_axis_iq_in_0
A25: G. Debug_008: all_zero to the DAC
A26: 1 | B26: signal_source_select (mem39) | C26: ="0x"&DEC2HEX(HEX2DEC(Summary!$B$3)+156,8) | D26: 00000002 | E26: all_zero (160'd0, tvalid = 1)
A27: 2 | B27: bypass_axis_iq (mem38) | C27: ="0x"&DEC2HEX(HEX2DEC(Summary!$B$3)+152,8) | D27: 00000001 | E27: DAC receives all zeros directly (0 = through FIR / cal / gain)
